[2023-04-28T13:36:11.412+0000] {taskinstance.py:1083} INFO - Dependencies all met for <TaskInstance: alfi7.connection_task scheduled__2020-04-22T00:00:00+00:00 [queued]>
[2023-04-28T13:36:11.420+0000] {taskinstance.py:1083} INFO - Dependencies all met for <TaskInstance: alfi7.connection_task scheduled__2020-04-22T00:00:00+00:00 [queued]>
[2023-04-28T13:36:11.420+0000] {taskinstance.py:1279} INFO - 
--------------------------------------------------------------------------------
[2023-04-28T13:36:11.421+0000] {taskinstance.py:1280} INFO - Starting attempt 1 of 2
[2023-04-28T13:36:11.421+0000] {taskinstance.py:1281} INFO - 
--------------------------------------------------------------------------------
[2023-04-28T13:36:11.433+0000] {taskinstance.py:1300} INFO - Executing <Task(PythonOperator): connection_task> on 2020-04-22 00:00:00+00:00
[2023-04-28T13:36:11.438+0000] {standard_task_runner.py:55} INFO - Started process 8378 to run task
[2023-04-28T13:36:11.441+0000] {standard_task_runner.py:82} INFO - Running: ['***', 'tasks', 'run', 'alfi7', 'connection_task', 'scheduled__2020-04-22T00:00:00+00:00', '--job-id', '29', '--raw', '--subdir', 'DAGS_FOLDER/my_test_dag.py', '--cfg-path', '/tmp/tmp0stamyzx']
[2023-04-28T13:36:11.441+0000] {standard_task_runner.py:83} INFO - Job 29: Subtask connection_task
[2023-04-28T13:36:11.495+0000] {task_command.py:388} INFO - Running <TaskInstance: alfi7.connection_task scheduled__2020-04-22T00:00:00+00:00 [running]> on host 6cc0522fbd3b
[2023-04-28T13:36:11.549+0000] {taskinstance.py:1509} INFO - Exporting the following env vars:
AIRFLOW_CTX_DAG_OWNER=Caffeinated Quantum Squadron
AIRFLOW_CTX_DAG_ID=alfi7
AIRFLOW_CTX_TASK_ID=connection_task
AIRFLOW_CTX_EXECUTION_DATE=2020-04-22T00:00:00+00:00
AIRFLOW_CTX_TRY_NUMBER=1
AIRFLOW_CTX_DAG_RUN_ID=scheduled__2020-04-22T00:00:00+00:00
[2023-04-28T13:36:11.556+0000] {taskinstance.py:1768} ERROR - Task failed with exception
Traceback (most recent call last):
  File "/home/airflow/.local/lib/python3.7/site-packages/airflow/operators/python.py", line 175, in execute
    return_value = self.execute_callable()
  File "/home/airflow/.local/lib/python3.7/site-packages/airflow/operators/python.py", line 192, in execute_callable
    return self.python_callable(*self.op_args, **self.op_kwargs)
  File "/opt/airflow/dags/my_test_dag.py", line 79, in postres_conn
    db.create_connection()
  File "/opt/airflow/dags/database.py", line 17, in create_connection
    connection = Variable.get(connection_id, deserialize_json=True)
  File "/home/airflow/.local/lib/python3.7/site-packages/airflow/models/variable.py", line 141, in get
    raise KeyError(f"Variable {key} does not exist")
KeyError: 'Variable lilbaby does not exist'
[2023-04-28T13:36:11.568+0000] {taskinstance.py:1323} INFO - Marking task as UP_FOR_RETRY. dag_id=alfi7, task_id=connection_task, execution_date=20200422T000000, start_date=20230428T133611, end_date=20230428T133611
[2023-04-28T13:36:11.577+0000] {standard_task_runner.py:105} ERROR - Failed to execute job 29 for task connection_task ('Variable lilbaby does not exist'; 8378)
[2023-04-28T13:36:11.613+0000] {local_task_job.py:208} INFO - Task exited with return code 1
[2023-04-28T13:36:11.627+0000] {taskinstance.py:2578} INFO - 0 downstream tasks scheduled from follow-on schedule check
