[2023-04-28T13:36:50.642+0000] {taskinstance.py:1083} INFO - Dependencies all met for <TaskInstance: alfi8.connection_task scheduled__2020-04-22T00:00:00+00:00 [queued]>
[2023-04-28T13:36:50.650+0000] {taskinstance.py:1083} INFO - Dependencies all met for <TaskInstance: alfi8.connection_task scheduled__2020-04-22T00:00:00+00:00 [queued]>
[2023-04-28T13:36:50.650+0000] {taskinstance.py:1279} INFO - 
--------------------------------------------------------------------------------
[2023-04-28T13:36:50.651+0000] {taskinstance.py:1280} INFO - Starting attempt 1 of 2
[2023-04-28T13:36:50.651+0000] {taskinstance.py:1281} INFO - 
--------------------------------------------------------------------------------
[2023-04-28T13:36:50.665+0000] {taskinstance.py:1300} INFO - Executing <Task(PythonOperator): connection_task> on 2020-04-22 00:00:00+00:00
[2023-04-28T13:36:50.669+0000] {standard_task_runner.py:55} INFO - Started process 8487 to run task
[2023-04-28T13:36:50.672+0000] {standard_task_runner.py:82} INFO - Running: ['***', 'tasks', 'run', 'alfi8', 'connection_task', 'scheduled__2020-04-22T00:00:00+00:00', '--job-id', '36', '--raw', '--subdir', 'DAGS_FOLDER/my_test_dag.py', '--cfg-path', '/tmp/tmpxp0_gi8a']
[2023-04-28T13:36:50.673+0000] {standard_task_runner.py:83} INFO - Job 36: Subtask connection_task
[2023-04-28T13:36:50.726+0000] {task_command.py:388} INFO - Running <TaskInstance: alfi8.connection_task scheduled__2020-04-22T00:00:00+00:00 [running]> on host 6cc0522fbd3b
[2023-04-28T13:36:50.782+0000] {taskinstance.py:1509} INFO - Exporting the following env vars:
AIRFLOW_CTX_DAG_OWNER=Caffeinated Quantum Squadron
AIRFLOW_CTX_DAG_ID=alfi8
AIRFLOW_CTX_TASK_ID=connection_task
AIRFLOW_CTX_EXECUTION_DATE=2020-04-22T00:00:00+00:00
AIRFLOW_CTX_TRY_NUMBER=1
AIRFLOW_CTX_DAG_RUN_ID=scheduled__2020-04-22T00:00:00+00:00
[2023-04-28T13:36:50.788+0000] {taskinstance.py:1768} ERROR - Task failed with exception
Traceback (most recent call last):
  File "/home/airflow/.local/lib/python3.7/site-packages/airflow/operators/python.py", line 175, in execute
    return_value = self.execute_callable()
  File "/home/airflow/.local/lib/python3.7/site-packages/airflow/operators/python.py", line 192, in execute_callable
    return self.python_callable(*self.op_args, **self.op_kwargs)
  File "/opt/airflow/dags/my_test_dag.py", line 79, in postres_conn
    db.create_connection()
  File "/opt/airflow/dags/database.py", line 17, in create_connection
    connection = Variable.get(connection_id, deserialize_json=True)
  File "/home/airflow/.local/lib/python3.7/site-packages/airflow/models/variable.py", line 141, in get
    raise KeyError(f"Variable {key} does not exist")
KeyError: 'Variable lilbaby does not exist'
[2023-04-28T13:36:50.797+0000] {taskinstance.py:1323} INFO - Marking task as UP_FOR_RETRY. dag_id=alfi8, task_id=connection_task, execution_date=20200422T000000, start_date=20230428T133650, end_date=20230428T133650
[2023-04-28T13:36:50.806+0000] {standard_task_runner.py:105} ERROR - Failed to execute job 36 for task connection_task ('Variable lilbaby does not exist'; 8487)
[2023-04-28T13:36:50.845+0000] {local_task_job.py:208} INFO - Task exited with return code 1
[2023-04-28T13:36:50.860+0000] {taskinstance.py:2578} INFO - 0 downstream tasks scheduled from follow-on schedule check
